Workbook

Sheet README
B2: 항암요법 공고 레지멘 계산 DB
B3: HIRA 「암환자에게 처방·투여하는 약제에 대한 요양급여의 적용기준 및 방법에 관한 세부사항」 기반
B5: 출처 (공고) | C5: 건강보험심사평가원 공고 제2025-210호 (2025.10.1. 시행) / 발간 G000DB5-2025-140 (2025.12)
B6: 암종 분류 체계 | C6: 공고 본문 '주요 암종별 항암요법' 40개 카테고리 (1.소세포폐암 ~ 40.기타 항암제 병용요법)
B7: 용량 데이터 원칙 | C7: 공고 본문은 mg/m² 상세 용량을 명시하지 않고 '식약처 허가사항 기준'(일반원칙 3.가)으로 위임함. 따라서 본 DB의 용법용량은 NCCN / 허가사항 / 표준 임상 레퍼런스로 보완 입력하였으며 '출처'·'검증' 컬럼에 표기.
B9: ★ 사용법
B10: 1) 계산기 시트 | C10: 환자 키·체중·나이·성별·혈청크레아티닌(SCr) 입력 → BSA(Mosteller/DuBois), CrCl(Cockcroft-Gault), Calvert용 GFR 자동 산출
B11: 2) 레지멘DB 시트 | C11: 입력한 환자값 기준으로 모든 약제의 '1회용량(mg)'·'주기총량(mg)'이 자동 계산됨 (계산기 시트값을 실시간 참조)
B12: 3) 키트루다_적응증 | C12: pembrolizumab 국내 급여 13개 암종 전체. 용법 200mg q3w / 400mg q6w 고정. 기존 4종 + 2026.1 신규 9종.
B13: 4) 단위 규칙 | C13: mg/m²→×BSA / mg/m²/day→×BSA / mg/kg→×체중 / AUC→Calvert(AUC×(GFR+25)) / mg→고정용량(경구·IO 고정)
B15: ⚠ 면책 / 검증 | C15: 본 DB는 레지멘 용량 '계산 보조' 도구입니다. 실제 처방은 반드시 최신 식약처 허가사항·공고 본문·기관 프로토콜과 대조하여 검증해야 합니다. '검증' 컬럼이 '검증필요'인 행은 미확정 상태로 간주하십시오.
B16: 현재 버전 | C16: v2. 144개 레지멘/252 약제행. 10대 암(갑상선·대장·폐·유방·위·전립선·간·췌장·신장·담낭담도) comprehensive 반영 + 키트루다 13개 암종 전체. 130개 레지멘 NCCN v2025 대조 검증 완료, 14개 검증필요(소아·희귀암 위주).
B18: 투여요법 약어 | C18: N=선행화학요법(neoadjuvant) / A=수술후보조요법(adjuvant) / P=고식적요법(palliative) / S=구제요법(salvage)
C19: 관해유도(induction) / 관해공고(consolidation) / 관해유지(maintenance) / 강화(intensification) / CNS예방(prophylaxis)
B20: 투여경로 약어 | C20: IV=정맥내 / PO=경구 / SC=피하 / IM=근육내 / IT=척수강내
B21: 약제군 (1군/2군) | C21: 2군=암질환심의위원회가 별도 지정(투여대상·단계·요법 명시 적용). 1군=의학적 판단 하 허가범위 사용. '약제군' 시트 참조

Sheet 계산기
B2: 환자 파라미터 입력 → 체표면적·신기능 자동계산
B4: ■ 입력값 (노란색 셀)
B5: 키 (Height) | C5: 165 | D5: cm | E5: 예: 165
B6: 체중 (Weight) | C6: 62 | D6: kg | E6: 예: 62
B7: 나이 (Age) | C7: 60 | D7: 세 | E7: Cockcroft-Gault용
B8: 성별 (Sex) | C8: M | D8: M/F | E8: 여성이면 F 입력 (CrCl ×0.85)
B9: 혈청크레아티닌 (SCr) | C9: 0.9 | D9: mg/dL | E9: 예: 0.9
B11: ■ 자동 계산값 (녹색 셀)
B12: BSA – Mosteller | C12: =SQRT(C5*C6/3600) -> 1.6857244 | D12: m² | E12: 산식: √(키×체중/3600)
B13: BSA – DuBois | C13: =0.007184*C5^0.725*C6^0.425 -> 1.6819328 | D13: m² | E13: 산식: 0.007184×키^0.725×체중^0.425
B14: 적용 BSA | C14: =C12 -> 1.6857244 | D14: m² | E14: 레지멘DB 계산에 사용 (기본=Mosteller)
B15: CrCl – Cockcroft-Gault | C15: =((140-C7)*C6*IF(C8="F",0.85,1))/(72*C9) -> 76.54321 | D15: mL/min | E15: 산식: (140−나이)×체중×성별계수 / (72×SCr)
B16: 적용 GFR (Calvert, ≤125 cap) | C16: =MIN(C15,125) -> 76.54321 | D16: mL/min | E16: carboplatin AUC 용량 산정용
B18: 참고: Calvert 식 → carboplatin 용량(mg) = 목표AUC × (적용GFR + 25). 적용GFR은 과다추정 방지 위해 125 mL/min로 상한.

Sheet 레지멘DB
A1: 레지멘ID | B1: 암종번호 | C1: 암종 | D1: 레지멘명 | E1: 투여요법 | F1: 투여단계 | G1: 약제성분 | H1: 약제군 | I1: 용량값 | J1: 단위 | K1: 투여일 | L1: 회수/주기 | M1: 주기길이(일) | N1: 주기표기 | O1: 총사이클 | P1: 경로 | Q1: 비고/상한 | R1: 1회용량(mg) | S1: 주기총량(mg) | T1: 출처 | U1: 검증
A2: 1-EP | B2: 1 | C2: 소세포폐암 | D2: EP (Etoposide+Cisplatin) | E2: P/공고 | F2: 1차 | G2: Etoposide | H2: 1 | I2: 100 | J2: mg/m² | K2: D1-3 | L2: 3 | M2: 21 | N2: q3w | O2: 4 | P2: IV | R2: =IF(N(I2)=0,"",IF(OR(J2="mg/m²",J2="mg/m²/day"),I2*계산기!$C$14,IF(J2="mg/kg",I2*계산기!$C$6,IF(J2="AUC",I2*(계산기!$C$16+25),IF(J2="mg",I2,""))))) -> 168.57244 | S2: =IF(OR(R2="",L2=""),"",R2*L2) -> 505.71731 | T2: NCCN v2025/허가사항 | U2: NCCN확인
G3: Cisplatin | H3: 1 | I3: 75 | J3: mg/m² | K3: D1 | L3: 1 | M3: 21 | N3: q3w | O3: 4 | P3: IV | Q3: 60-80 범위 | R3: =IF(N(I3)=0,"",IF(OR(J3="mg/m²",J3="mg/m²/day"),I3*계산기!$C$14,IF(J3="mg/kg",I3*계산기!$C$6,IF(J3="AUC",I3*(계산기!$C$16+25),IF(J3="mg",I3,""))))) -> 126.42933 | S3: =IF(OR(R3="",L3=""),"",R3*L3) -> 126.42933
A4: 1-EC | B4: 1 | C4: 소세포폐암 | D4: EC (Etoposide+Carboplatin) | E4: P | F4: 1차 | G4: Etoposide | H4: 1 | I4: 100 | J4: mg/m² | K4: D1-3 | L4: 3 | M4: 21 | N4: q3w | O4: 4 | P4: IV | R4: =IF(N(I4)=0,"",IF(OR(J4="mg/m²",J4="mg/m²/day"),I4*계산기!$C$14,IF(J4="mg/kg",I4*계산기!$C$6,IF(J4="AUC",I4*(계산기!$C$16+25),IF(J4="mg",I4,""))))) -> 168.57244 | S4: =IF(OR(R4="",L4=""),"",R4*L4) -> 505.71731 | T4: NCCN v2025/허가사항 | U4: NCCN확인
G5: Carboplatin | H5: 1 | I5: 5 | J5: AUC | K5: D1 | L5: 1 | M5: 21 | N5: q3w | O5: 4 | P5: IV | Q5: AUC 5-6 | R5: =IF(N(I5)=0,"",IF(OR(J5="mg/m²",J5="mg/m²/day"),I5*계산기!$C$14,IF(J5="mg/kg",I5*계산기!$C$6,IF(J5="AUC",I5*(계산기!$C$16+25),IF(J5="mg",I5,""))))) -> 507.71605 | S5: =IF(OR(R5="",L5=""),"",R5*L5) -> 507.71605
A6: 1-Atezolizumab | B6: 1 | C6: 소세포폐암 | D6: Atezolizumab + CE | E6: P | F6: 1차 | G6: Atezolizumab | H6: 2 | I6: 1200 | J6: mg | K6: D1 | L6: 1 | M6: 21 | N6: q3w | P6: IV | Q6: 고정용량 | R6: =IF(N(I6)=0,"",IF(OR(J6="mg/m²",J6="mg/m²/day"),I6*계산기!$C$14,IF(J6="mg/kg",I6*계산기!$C$6,IF(J6="AUC",I6*(계산기!$C$16+25),IF(J6="mg",I6,""))))) -> 1200 | S6: =IF(OR(R6="",L6=""),"",R6*L6) -> 1200 | T6: NCCN v2025/허가사항 | U6: NCCN확인
G7: Carboplatin | H7: 1 | I7: 5 | J7: AUC | K7: D1 | L7: 1 | M7: 21 | N7: q3w | O7: 4 | P7: IV | R7: =IF(N(I7)=0,"",IF(OR(J7="mg/m²",J7="mg/m²/day"),I7*계산기!$C$14,IF(J7="mg/kg",I7*계산기!$C$6,IF(J7="AUC",I7*(계산기!$C$16+25),IF(J7="mg",I7,""))))) -> 507.71605 | S7: =IF(OR(R7="",L7=""),"",R7*L7) -> 507.71605
G8: Etoposide | H8: 1 | I8: 100 | J8: mg/m² | K8: D1-3 | L8: 3 | M8: 21 | N8: q3w | O8: 4 | P8: IV | R8: =IF(N(I8)=0,"",IF(OR(J8="mg/m²",J8="mg/m²/day"),I8*계산기!$C$14,IF(J8="mg/kg",I8*계산기!$C$6,IF(J8="AUC",I8*(계산기!$C$16+25),IF(J8="mg",I8,""))))) -> 168.57244 | S8: =IF(OR(R8="",L8=""),"",R8*L8) -> 505.71731
A9: 1-Topotecan | B9: 1 | C9: 소세포폐암 | D9: Topotecan | E9: P/S | F9: 2차 이상 | G9: Topotecan | H9: 1 | I9: 1.5 | J9: mg/m² | K9: D1-5 | L9: 5 | M9: 21 | N9: q3w | P9: IV | R9: =IF(N(I9)=0,"",IF(OR(J9="mg/m²",J9="mg/m²/day"),I9*계산기!$C$14,IF(J9="mg/kg",I9*계산기!$C$6,IF(J9="AUC",I9*(계산기!$C$16+25),IF(J9="mg",I9,""))))) -> 2.5285866 | S9: =IF(OR(R9="",L9=""),"",R9*L9) -> 12.642933 | T9: NCCN v2025/허가사항 | U9: NCCN확인
A10: 2-Pemetrexed+Cis | B10: 2 | C10: 비소세포폐암 | D10: Pemetrexed+Cisplatin | E10: P/A | F10: 1차 | G10: Pemetrexed | H10: 1 | I10: 500 | J10: mg/m² | K10: D1 | L10: 1 | M10: 21 | N10: q3w | O10: 4 | P10: IV | Q10: 비편평 | R10: =IF(N(I10)=0,"",IF(OR(J10="mg/m²",J10="mg/m²/day"),I10*계산기!$C$14,IF(J10="mg/kg",I10*계산기!$C$6,IF(J10="AUC",I10*(계산기!$C$16+25),IF(J10="mg",I10,""))))) -> 842.86219 | S10: =IF(OR(R10="",L10=""),"",R10*L10) -> 842.86219 | T10: NCCN v2025/허가사항 | U10: NCCN확인
G11: Cisplatin | H11: 1 | I11: 75 | J11: mg/m² | K11: D1 | L11: 1 | M11: 21 | N11: q3w | O11: 4 | P11: IV | R11: =IF(N(I11)=0,"",IF(OR(J11="mg/m²",J11="mg/m²/day"),I11*계산기!$C$14,IF(J11="mg/kg",I11*계산기!$C$6,IF(J11="AUC",I11*(계산기!$C$16+25),IF(J11="mg",I11,""))))) -> 126.42933 | S11: =IF(OR(R11="",L11=""),"",R11*L11) -> 126.42933
A12: 2-Paclitaxel+Car | B12: 2 | C12: 비소세포폐암 | D12: Paclitaxel+Carboplatin | E12: P | F12: 1차 | G12: Paclitaxel | H12: 1 | I12: 200 | J12: mg/m² | K12: D1 | L12: 1 | M12: 21 | N12: q3w | O12: 4 | P12: IV | R12: =IF(N(I12)=0,"",IF(OR(J12="mg/m²",J12="mg/m²/day"),I12*계산기!$C$14,IF(J12="mg/kg",I12*계산기!$C$6,IF(J12="AUC",I12*(계산기!$C$16+25),IF(J12="mg",I12,""))))) -> 337.14487 | S12: =IF(OR(R12="",L12=""),"",R12*L12) -> 337.14487 | T12: NCCN v2025/허가사항 | U12: NCCN확인
G13: Carboplatin | H13: 1 | I13: 6 | J13: AUC | K13: D1 | L13: 1 | M13: 21 | N13: q3w | O13: 4 | P13: IV | R13: =IF(N(I13)=0,"",IF(OR(J13="mg/m²",J13="mg/m²/day"),I13*계산기!$C$14,IF(J13="mg/kg",I13*계산기!$C$6,IF(J13="AUC",I13*(계산기!$C$16+25),IF(J13="mg",I13,""))))) -> 609.25926 | S13: =IF(OR(R13="",L13=""),"",R13*L13) -> 609.25926
A14: 2-Gemcitabine+Ci | B14: 2 | C14: 비소세포폐암 | D14: Gemcitabine+Cisplatin | E14: P | F14: 1차 | G14: Gemcitabine | H14: 1 | I14: 1250 | J14: mg/m² | K14: D1,8 | L14: 2 | M14: 21 | N14: q3w | O14: 4 | P14: IV | R14: =IF(N(I14)=0,"",IF(OR(J14="mg/m²",J14="mg/m²/day"),I14*계산기!$C$14,IF(J14="mg/kg",I14*계산기!$C$6,IF(J14="AUC",I14*(계산기!$C$16+25),IF(J14="mg",I14,""))))) -> 2107.1555 | S14: =IF(OR(R14="",L14=""),"",R14*L14) -> 4214.3109 | T14: NCCN v2025/허가사항 | U14: NCCN확인
G15: Cisplatin | H15: 1 | I15: 75 | J15: mg/m² | K15: D1 | L15: 1 | M15: 21 | N15: q3w | O15: 4 | P15: IV | R15: =IF(N(I15)=0,"",IF(OR(J15="mg/m²",J15="mg/m²/day"),I15*계산기!$C$14,IF(J15="mg/kg",I15*계산기!$C$6,IF(J15="AUC",I15*(계산기!$C$16+25),IF(J15="mg",I15,""))))) -> 126.42933 | S15: =IF(OR(R15="",L15=""),"",R15*L15) -> 126.42933
A16: 2-Docetaxel | B16: 2 | C16: 비소세포폐암 | D16: Docetaxel | E16: P/S | F16: 2차 이상 | G16: Docetaxel | H16: 1 | I16: 75 | J16: mg/m² | K16: D1 | L16: 1 | M16: 21 | N16: q3w | P16: IV | R16: =IF(N(I16)=0,"",IF(OR(J16="mg/m²",J16="mg/m²/day"),I16*계산기!$C$14,IF(J16="mg/kg",I16*계산기!$C$6,IF(J16="AUC",I16*(계산기!$C$16+25),IF(J16="mg",I16,""))))) -> 126.42933 | S16: =IF(OR(R16="",L16=""),"",R16*L16) -> 126.42933 | T16: NCCN v2025/허가사항 | U16: NCCN확인
A17: 2-Pembrolizumab | B17: 2 | C17: 비소세포폐암 | D17: Pembrolizumab 단독 | E17: P | F17: 1차 | G17: Pembrolizumab | H17: 2 | I17: 200 | J17: mg | K17: D1 | L17: 1 | M17: 21 | N17: q3w | P17: IV | Q17: PD-L1≥50%; 400mg q6w 가능 | R17: =IF(N(I17)=0,"",IF(OR(J17="mg/m²",J17="mg/m²/day"),I17*계산기!$C$14,IF(J17="mg/kg",I17*계산기!$C$6,IF(J17="AUC",I17*(계산기!$C$16+25),IF(J17="mg",I17,""))))) -> 200 | S17: =IF(OR(R17="",L17=""),"",R17*L17) -> 200 | T17: NCCN v2025/허가사항 | U17: NCCN확인
A18: 2-Osimertinib | B18: 2 | C18: 비소세포폐암 | D18: Osimertinib | E18: P/A | F18: 1차 | G18: Osimertinib | H18: 2 | I18: 80 | J18: mg | K18: 매일 | L18: 1 | M18: 1 | N18: daily | O18: 연속 | P18: PO | Q18: EGFR변이 | R18: =IF(N(I18)=0,"",IF(OR(J18="mg/m²",J18="mg/m²/day"),I18*계산기!$C$14,IF(J18="mg/kg",I18*계산기!$C$6,IF(J18="AUC",I18*(계산기!$C$16+25),IF(J18="mg",I18,""))))) -> 80 | S18: =IF(OR(R18="",L18=""),"",R18*L18) -> 80 | T18: NCCN v2025/허가사항 | U18: NCCN확인
A19: 2-Gefitinib | B19: 2 | C19: 비소세포폐암 | D19: Gefitinib | E19: P | F19: 1차 이상 | G19: Gefitinib | H19: 2 | I19: 250 | J19: mg | K19: 매일 | L19: 1 | M19: 1 | N19: daily | O19: 연속 | P19: PO | Q19: EGFR변이 | R19: =IF(N(I19)=0,"",IF(OR(J19="mg/m²",J19="mg/m²/day"),I19*계산기!$C$14,IF(J19="mg/kg",I19*계산기!$C$6,IF(J19="AUC",I19*(계산기!$C$16+25),IF(J19="mg",I19,""))))) -> 250 | S19: =IF(OR(R19="",L19=""),"",R19*L19) -> 250 | T19: NCCN v2025/허가사항 | U19: NCCN확인
A20: 2-Alectinib | B20: 2 | C20: 비소세포폐암 | D20: Alectinib | E20: P | F20: 1차 | G20: Alectinib | H20: 2 | I20: 600 | J20: mg | K20: BID | L20: 2 | M20: 1 | N20: daily | O20: 연속 | P20: PO | Q20: ALK양성 | R20: =IF(N(I20)=0,"",IF(OR(J20="mg/m²",J20="mg/m²/day"),I20*계산기!$C$14,IF(J20="mg/kg",I20*계산기!$C$6,IF(J20="AUC",I20*(계산기!$C$16+25),IF(J20="mg",I20,""))))) -> 600 | S20: =IF(OR(R20="",L20=""),"",R20*L20) -> 1200 | T20: NCCN v2025/허가사항 | U20: NCCN확인
A21: 3-mFOLFOX6 | B21: 3 | C21: 위암 | D21: mFOLFOX6 | E21: P/A | F21: 1차 | G21: Oxaliplatin | H21: 1 | I21: 85 | J21: mg/m² | K21: D1 | L21: 1 | M21: 14 | N21: q2w | P21: IV | R21: =IF(N(I21)=0,"",IF(OR(J21="mg/m²",J21="mg/m²/day"),I21*계산기!$C$14,IF(J21="mg/kg",I21*계산기!$C$6,IF(J21="AUC",I21*(계산기!$C$16+25),IF(J21="mg",I21,""))))) -> 143.28657 | S21: =IF(OR(R21="",L21=""),"",R21*L21) -> 143.28657 | T21: NCCN v2025/허가사항 | U21: NCCN확인
G22: Leucovorin | H22: 1 | I22: 400 | J22: mg/m² | K22: D1 | L22: 1 | M22: 14 | N22: q2w | P22: IV | R22: =IF(N(I22)=0,"",IF(OR(J22="mg/m²",J22="mg/m²/day"),I22*계산기!$C$14,IF(J22="mg/kg",I22*계산기!$C$6,IF(J22="AUC",I22*(계산기!$C$16+25),IF(J22="mg",I22,""))))) -> 674.28975 | S22: =IF(OR(R22="",L22=""),"",R22*L22) -> 674.28975
G23: Fluorouracil(bolus) | H23: 1 | I23: 400 | J23: mg/m² | K23: D1 | L23: 1 | M23: 14 | N23: q2w | P23: IV | R23: =IF(N(I23)=0,"",IF(OR(J23="mg/m²",J23="mg/m²/day"),I23*계산기!$C$14,IF(J23="mg/kg",I23*계산기!$C$6,IF(J23="AUC",I23*(계산기!$C$16+25),IF(J23="mg",I23,""))))) -> 674.28975 | S23: =IF(OR(R23="",L23=""),"",R23*L23) -> 674.28975
G24: Fluorouracil(CI) | H24: 1 | I24: 2400 | J24: mg/m² | K24: D1-2 | L24: 1 | M24: 14 | N24: q2w | P24: IV | Q24: 46시간 지속주입 | R24: =IF(N(I24)=0,"",IF(OR(J24="mg/m²",J24="mg/m²/day"),I24*계산기!$C$14,IF(J24="mg/kg",I24*계산기!$C$6,IF(J24="AUC",I24*(계산기!$C$16+25),IF(J24="mg",I24,""))))) -> 4045.7385 | S24: =IF(OR(R24="",L24=""),"",R24*L24) -> 4045.7385
A25: 3-XELOX | B25: 3 | C25: 위암 | D25: XELOX (CapeOx) | E25: P/A | F25: 1차 | G25: Oxaliplatin | H25: 1 | I25: 130 | J25: mg/m² | K25: D1 | L25: 1 | M25: 21 | N25: q3w | P25: IV | R25: =IF(N(I25)=0,"",IF(OR(J25="mg/m²",J25="mg/m²/day"),I25*계산기!$C$14,IF(J25="mg/kg",I25*계산기!$C$6,IF(J25="AUC",I25*(계산기!$C$16+25),IF(J25="mg",I25,""))))) -> 219.14417 | S25: =IF(OR(R25="",L25=""),"",R25*L25) -> 219.14417 | T25: NCCN v2025/허가사항 | U25: NCCN확인
G26: Capecitabine | H26: 1 | I26: 1000 | J26: mg/m² | K26: D1-14 BID | L26: 2 | M26: 21 | N26: q3w | P26: PO | Q26: 1일 2회 | R26: =IF(N(I26)=0,"",IF(OR(J26="mg/m²",J26="mg/m²/day"),I26*계산기!$C$14,IF(J26="mg/kg",I26*계산기!$C$6,IF(J26="AUC",I26*(계산기!$C$16+25),IF(J26="mg",I26,""))))) -> 1685.7244 | S26: =IF(OR(R26="",L26=""),"",R26*L26) -> 3371.4487
A27: 3-Trastuzumab+Ca | B27: 3 | C27: 위암 | D27: Trastuzumab+CapeOx | E27: P | F27: 1차 | G27: Trastuzumab | H27: 2 | I27: 6 | J27: mg/kg | K27: D1 | L27: 1 | M27: 21 | N27: q3w | P27: IV | Q27: HER2+; 초회 8mg/kg | R27: =IF(N(I27)=0,"",IF(OR(J27="mg/m²",J27="mg/m²/day"),I27*계산기!$C$14,IF(J27="mg/kg",I27*계산기!$C$6,IF(J27="AUC",I27*(계산기!$C$16+25),IF(J27="mg",I27,""))))) -> 372 | S27: =IF(OR(R27="",L27=""),"",R27*L27) -> 372 | T27: NCCN v2025/허가사항 | U27: NCCN확인
G28: Capecitabine | H28: 1 | I28: 1000 | J28: mg/m² | K28: D1-14 BID | L28: 2 | M28: 21 | N28: q3w | P28: PO | R28: =IF(N(I28)=0,"",IF(OR(J28="mg/m²",J28="mg/m²/day"),I28*계산기!$C$14,IF(J28="mg/kg",I28*계산기!$C$6,IF(J28="AUC",I28*(계산기!$C$16+25),IF(J28="mg",I28,""))))) -> 1685.7244 | S28: =IF(OR(R28="",L28=""),"",R28*L28) -> 3371.4487
G29: Oxaliplatin | H29: 1 | I29: 130 | J29: mg/m² | K29: D1 | L29: 1 | M29: 21 | N29: q3w | P29: IV | R29: =IF(N(I29)=0,"",IF(OR(J29="mg/m²",J29="mg/m²/day"),I29*계산기!$C$14,IF(J29="mg/kg",I29*계산기!$C$6,IF(J29="AUC",I29*(계산기!$C$16+25),IF(J29="mg",I29,""))))) -> 219.14417 | S29: =IF(OR(R29="",L29=""),"",R29*L29) -> 219.14417
A30: 3-Ramucirumab+Pa | B30: 3 | C30: 위암 | D30: Ramucirumab+Paclitaxel | E30: P | F30: 2차 | G30: Ramucirumab | H30: 2 | I30: 8 | J30: mg/kg | K30: D1,15 | L30: 2 | M30: 28 | N30: q4w | P30: IV | R30: =IF(N(I30)=0,"",IF(OR(J30="mg/m²",J30="mg/m²/day"),I30*계산기!$C$14,IF(J30="mg/kg",I30*계산기!$C$6,IF(J30="AUC",I30*(계산기!$C$16+25),IF(J30="mg",I30,""))))) -> 496 | S30: =IF(OR(R30="",L30=""),"",R30*L30) -> 992 | T30: NCCN v2025/허가사항 | U30: NCCN확인
G31: Paclitaxel | H31: 1 | I31: 80 | J31: mg/m² | K31: D1,8,15 | L31: 3 | M31: 28 | N31: q4w | P31: IV | R31: =IF(N(I31)=0,"",IF(OR(J31="mg/m²",J31="mg/m²/day"),I31*계산기!$C$14,IF(J31="mg/kg",I31*계산기!$C$6,IF(J31="AUC",I31*(계산기!$C$16+25),IF(J31="mg",I31,""))))) -> 134.85795 | S31: =IF(OR(R31="",L31=""),"",R31*L31) -> 404.57385
A32: 4-CROSS | B32: 4 | C32: 식도암 | D32: CROSS (CRT) | E32: N | F32: 수술전 | G32: Paclitaxel | H32: 1 | I32: 50 | J32: mg/m² | K32: weekly | L32: 5 | M32: 7 | N32: weekly | O32: 5 | P32: IV | Q32: 방사선 병용 | R32: =IF(N(I32)=0,"",IF(OR(J32="mg/m²",J32="mg/m²/day"),I32*계산기!$C$14,IF(J32="mg/kg",I32*계산기!$C$6,IF(J32="AUC",I32*(계산기!$C$16+25),IF(J32="mg",I32,""))))) -> 84.286219 | S32: =IF(OR(R32="",L32=""),"",R32*L32) -> 421.43109 | T32: NCCN v2025/허가사항 | U32: NCCN확인
G33: Carboplatin | H33: 1 | I33: 2 | J33: AUC | K33: weekly | L33: 5 | M33: 7 | N33: weekly | O33: 5 | P33: IV | Q33: 방사선 병용 | R33: =IF(N(I33)=0,"",IF(OR(J33="mg/m²",J33="mg/m²/day"),I33*계산기!$C$14,IF(J33="mg/kg",I33*계산기!$C$6,IF(J33="AUC",I33*(계산기!$C$16+25),IF(J33="mg",I33,""))))) -> 203.08642 | S33: =IF(OR(R33="",L33=""),"",R33*L33) -> 1015.4321
A34: 4-FP | B34: 4 | C34: 식도암 | D34: FP (5-FU+Cisplatin) | E34: P/N | F34: 1차 | G34: Fluorouracil | H34: 1 | I34: 1000 | J34: mg/m² | K34: D1-4 | L34: 1 | M34: 28 | N34: q4w | P34: IV | Q34: 지속주입 | R34: =IF(N(I34)=0,"",IF(OR(J34="mg/m²",J34="mg/m²/day"),I34*계산기!$C$14,IF(J34="mg/kg",I34*계산기!$C$6,IF(J34="AUC",I34*(계산기!$C$16+25),IF(J34="mg",I34,""))))) -> 1685.7244 | S34: =IF(OR(R34="",L34=""),"",R34*L34) -> 1685.7244 | T34: NCCN v2025/허가사항 | U34: NCCN확인
G35: Cisplatin | H35: 1 | I35: 75 | J35: mg/m² | K35: D1 | L35: 1 | M35: 28 | N35: q4w | P35: IV | R35: =IF(N(I35)=0,"",IF(OR(J35="mg/m²",J35="mg/m²/day"),I35*계산기!$C$14,IF(J35="mg/kg",I35*계산기!$C$6,IF(J35="AUC",I35*(계산기!$C$16+25),IF(J35="mg",I35,""))))) -> 126.42933 | S35: =IF(OR(R35="",L35=""),"",R35*L35) -> 126.42933
A36: 5-Lenvatinib | B36: 5 | C36: 갑상선암 | D36: Lenvatinib | E36: P | F36: 1차 | G36: Lenvatinib | H36: 2 | I36: 24 | J36: mg | K36: 매일 | L36: 1 | M36: 1 | N36: daily | O36: 연속 | P36: PO | Q36: RAI불응 분화암 | R36: =IF(N(I36)=0,"",IF(OR(J36="mg/m²",J36="mg/m²/day"),I36*계산기!$C$14,IF(J36="mg/kg",I36*계산기!$C$6,IF(J36="AUC",I36*(계산기!$C$16+25),IF(J36="mg",I36,""))))) -> 24 | S36: =IF(OR(R36="",L36=""),"",R36*L36) -> 24 | T36: NCCN v2025/허가사항 | U36: NCCN확인
A37: 5-Sorafenib | B37: 5 | C37: 갑상선암 | D37: Sorafenib | E37: P | F37: 1차 | G37: Sorafenib | H37: 2 | I37: 400 | J37: mg | K37: BID | L37: 2 | M37: 1 | N37: daily | O37: 연속 | P37: PO | R37: =IF(N(I37)=0,"",IF(OR(J37="mg/m²",J37="mg/m²/day"),I37*계산기!$C$14,IF(J37="mg/kg",I37*계산기!$C$6,IF(J37="AUC",I37*(계산기!$C$16+25),IF(J37="mg",I37,""))))) -> 400 | S37: =IF(OR(R37="",L37=""),"",R37*L37) -> 800 | T37: NCCN v2025/허가사항 | U37: NCCN확인
A38: 6-FOLFIRINOX | B38: 6 | C38: 췌장암 | D38: FOLFIRINOX | E38: P/A | F38: 1차 | G38: Oxaliplatin | H38: 1 | I38: 85 | J38: mg/m² | K38: D1 | L38: 1 | M38: 14 | N38: q2w | P38: IV | R38: =IF(N(I38)=0,"",IF(OR(J38="mg/m²",J38="mg/m²/day"),I38*계산기!$C$14,IF(J38="mg/kg",I38*계산기!$C$6,IF(J38="AUC",I38*(계산기!$C$16+25),IF(J38="mg",I38,""))))) -> 143.28657 | S38: =IF(OR(R38="",L38=""),"",R38*L38) -> 143.28657 | T38: NCCN v2025/허가사항 | U38: NCCN확인
G39: Irinotecan | H39: 1 | I39: 180 | J39: mg/m² | K39: D1 | L39: 1 | M39: 14 | N39: q2w | P39: IV | R39: =IF(N(I39)=0,"",IF(OR(J39="mg/m²",J39="mg/m²/day"),I39*계산기!$C$14,IF(J39="mg/kg",I39*계산기!$C$6,IF(J39="AUC",I39*(계산기!$C$16+25),IF(J39="mg",I39,""))))) -> 303.43039 | S39: =IF(OR(R39="",L39=""),"",R39*L39) -> 303.43039
G40: Leucovorin | H40: 1 | I40: 400 | J40: mg/m² | K40: D1 | L40: 1 | M40: 14 | N40: q2w | P40: IV | R40: =IF(N(I40)=0,"",IF(OR(J40="mg/m²",J40="mg/m²/day"),I40*계산기!$C$14,IF(J40="mg/kg",I40*계산기!$C$6,IF(J40="AUC",I40*(계산기!$C$16+25),IF(J40="mg",I40,""))))) -> 674.28975 | S40: =IF(OR(R40="",L40=""),"",R40*L40) -> 674.28975
...

Sheet 암종분류
B2: HIRA 공고 '주요 암종별 항암요법' 분류 (공고 제2025-210호 목차 기준)
B4: 암종번호 | C4: 암종명 | D4: DB수록
B5: 1 | C5: 소세포폐암 | D5: ○
B6: 2 | C6: 비소세포폐암 | D6: ○
B7: 3 | C7: 위암 | D7: ○
B8: 4 | C8: 식도암 | D8: ○
B9: 5 | C9: 갑상선암 | D9: ○
B10: 6 | C10: 췌장암 | D10: ○
B11: 7-1 | C11: 간암 | D11: ○
B12: 7-2 | C12: 담도암 | D12: ○
B13: 8 | C13: 직결장암 | D13: ○
B14: 9 | C14: 유방암 | D14: ○
B15: 10 | C15: 난소암/난관암/일차복막암 | D15: ○
... B46: 40 | C46: 기타 항암제 병용요법(기존 항암요법 본인일부부담) | D46: –
C48: ○=v1 수록 / –=차기 확장 대상

Sheet 약제군_2군
B2: 2군 항암제 색인 (암질환심의위원회 지정) — 일반원칙 발췌
B3: 2군=투여대상·투여단계·투여요법이 공고에 명시된 약제. 미수록 성분은 1군(허가범위 내 의학적 판단 사용).
B5: 성분명 | C5: 관련 공고
B6: abemaciclib | C6: 제2020-155호
B7: abiraterone acetate | C7: 제2018-103호
B8: afatinib | C8: 제2014-187호
B9: alectinib | C9: 제2017-213호
B10: apalutamide | C10: 제2023-84호
B11: atezolizumab | C11: 제2018-10호
B12: avelumab | C12: 제2020-255호
B13: axitinib | C13: 제2018-162호
B14: bendamustine | C14: 제2018-210호
B15: bevacizumab | C15: 제2014-15호
B16: blinatumomab | C16: 제2016-259호
... B69: zanubrutinib | C69: 제2023-128호

Sheet 키트루다_적응증
B2: 키트루다(pembrolizumab) 국내 급여 적응증 — 13개 암종
B3: 용법용량(전 적응증 공통): 200mg IV q3w 또는 400mg IV q6w 고정용량 (체표면적·체중 무관). 급여인정기간 일반원칙: 1년(질병진행 시 중단), 임상결과 미발표 시 최대 2년 자동연장.
B4: 기존 급여 4종(폐·흑색종·호지킨·요로상피) + 2025년 제1차 암질심 신규 7개암종 11적응증(공고개정 2025-256호 계열, 2026.1.1 시행) 반영.
B6: 연번 | C6: 암종 | D6: 투여대상(바이오마커/병기) | E6: 투여단계 | F6: 병용요법 | G6: 근거시험 | H6: 급여구분 | I6: 검증
B7: 1 | C7: 비소세포폐암 | D7: PD-L1 TPS≥50%, EGFR/ALK 음성 | E7: 1차 | F7: 단독 | G7: KEYNOTE-024 | H7: 기존급여 | I7: 공고확인
B8: 1 | C8: 비소세포폐암 | D8: 전이성 비편평/편평 | E8: 1차 | F8: pemetrexed 또는 paclitaxel+백금 | G8: KEYNOTE-189/407 | H8: 기존급여 | I8: 공고확인
B9: 1 | C9: 비소세포폐암 | D9: PD-L1 TPS≥1% | E9: 2차 이상 | F9: 단독 | G9: KEYNOTE-010 | H9: 기존급여 | I9: 공고확인
B10: 2 | C10: 악성흑색종 | D10: 수술불가/전이성, PD-1/L1 naive | E10: 1차 이상 | F10: 단독 | G10: KEYNOTE-006 | H10: 기존급여 | I10: 공고확인
B11: 3 | C11: 호지킨림프종 | D11: 재발성 또는 불응성 cHL | E11: 2차 이상 | F11: 단독 | G11: KEYNOTE-204 | H11: 기존급여 | I11: 공고확인
B12: 4 | C12: 요로상피암 | D12: 백금 후 진행 또는 cisplatin 부적격 | E12: 2차/1차 | F12: 단독 | G12: KEYNOTE-045/052 | H12: 기존급여 | I12: 공고확인
B13: 5 | C13: 위/위식도접합부암 | D13: HER2+ & PD-L1 CPS≥1, 수술불가 국소진행/전이 | E13: 1차 | F13: trastuzumab+fluoropyrimidine+백금 | G13: KEYNOTE-811 | H13: 신규(2026.1) | I13: 공고확인
B14: 5 | C14: 위/위식도접합부암 | D14: HER2- & PD-L1 CPS≥10, 수술불가 국소진행/전이 | E14: 1차 | F14: fluoropyrimidine+백금 | G14: KEYNOTE-859 | H14: 신규(2026.1) | I14: 공고확인
B15: 6 | C15: 식도암 | D15: PD-L1 CPS≥10, 수술불가 국소진행/전이 | E15: 1차 | F15: 백금+fluoropyrimidine | G15: KEYNOTE-590 | H15: 신규(2026.1) | I15: 공고확인
B16: 7 | C16: 자궁내막암 | D16: pMMR(비MSI-H/비dMMR), 전신요법 후 진행 | E16: 2차 | F16: lenvatinib 병용 | G16: KEYNOTE-775 | H16: 신규(2026.1) | I16: 공고확인
B17: 7 | C17: 자궁내막암 | D17: MSI-H/dMMR, 치료 후 진행·대체옵션 없음 | E17: 2차 이상 | F17: 단독 | G17: KEYNOTE-158 | H17: 신규(2026.1) | I17: 공고확인
B18: 8 | C18: 직결장암 | D18: MSI-H/dMMR, 수술불가/전이성 | E18: 1차 | F18: 단독 | G18: KEYNOTE-177 | H18: 신규(2026.1) | I18: 공고확인
... B24: 13 | C24: 담도암 | D24: MSI-H/dMMR, 치료 후 진행·대체옵션 없음 | E24: 2차 이상 | F24: 단독 | G24: KEYNOTE-158 | H24: 신규(2026.1) | I24: 공고확인
C26: 검증: '공고확인'=2025 암질심 의결·공고개정 기준 일치. CPS/MSI 기준은 처방 시 최신 공고 본문으로 재확인 권장.
