Workbook
Name title: '[1]Central Control'!$C$9
Name Tx_1: '[1]Central Control'!$C$95
Name Tx_1a: '[1]Central Control'!$C$95
Name Tx_2: '[1]Central Control'!$C$96
Name Tx_2a: '[1]Central Control'!$C$96

Sheet Setting
B1: =title -> Budget impact model of belzutifan as a treatment for Von Hippel Lindau Disease-associated renal cell carcinoma, central nervous system hemangioblastoma, and pancreatic neuroendocrine tumor
A3: Settings
B5: Indication
B7: 폰히펠-린다우(von Hippel-Lindau, VHL)병 성인 환자에서 수술이 불가능하거나 수술이 적합하지 않은 신세포암, 중추신경계 혈관모세포종, 췌장 신경 내분비 종양의 치료
B9: General
C11: Country | G11: Korea
C12: Currency | G12: ₩
C13: Time horizon (years) | G13: 3
C14: Perspective | G14: payer
B16: Comparator
G18: Intervention | H18: belzutifan
G19: Comparator | H19: Active Survailunce
B21: Epidemiological data
B24: 1. 2021-2024년 Q85.8* 환자수 | G24: 연도(년) | H24: Q85.8 환자수(명)
G25: 2020 | H25: 1055
C26: *상병코드 Q85.8(달리 분류되지 않는 기타 모반증)은 폰 히펠-린다우 증후군, 포이츠 제거스 증후군, 스터지-베버(-디미트리) 증후군 등을 포함함. (단, 실제 임상 현장에서는 이 3개의 질환 외 다른 상세불명의 희귀질환에 대해서도 동 상병코드로 적용함을 확인함) | G26: 2021 | H26: 1125
G27: 2022 | H27: 1142
G28: 2023 | H28: 1286
G29: 2024 | H29: 1333
B33: 2. 2021-2024년 성인 VHL * 환자수 | G33: 연도(년) | H33: 성인 VHL 환자수(명)
G34: 2020 | H34: =H25*$C$37*$C$40 -> 269.31273
C35: ▶ Q85.8 내 VHL병 환자비율 적용하여 추정함 | G35: 2021 | H35: =H26*$C$37*$C$40 -> 287.18182
C36: Input | D36: Source | G36: 2022 | H36: =H27*$C$37*$C$40 -> 291.52145
C37: 0.27 | D37: Park TY 등(2015) | G37: 2023 | H37: =H28*$C$37*$C$40 -> 328.28073
C38: ▶ VHL병 성인 예상 환자수를 추정함 | G38: 2024 | H38: =H29*$C$37*$C$40 -> 340.27855
C39: Input | D39: Source | G39: 3개년 CAGR(연평균 증가율) | H39: =(H38/H36)^(1/2)-1 -> 0.080393649
C40: =1-3/55 -> 0.94545455 | D40: Park TY 등(2015)
B42: 3. 2025-2030년 VHL병 성인 예상 환자수 | G42: 연도(년) | H42: 성인 VHL병 환자수(명)
G43: 2025 | H43: =H38*(1+$H$39) -> 367.63478
G44: 2026 | H44: =H43*(1+$H$39) -> 397.19028
G45: 2027 | H45: =H44*(1+$H$39) -> 429.12186
G46: 2028 | H46: =H45*(1+$H$39) -> 463.62053
G47: 2029 | H47: =H46*(1+$H$39) -> 500.89268
G48: 2030 | H48: =H47*(1+$H$39) -> 541.16127

Sheet Epi_Population
B1: =title -> Budget impact model of belzutifan as a treatment for Von Hippel Lindau Disease-associated renal cell carcinoma, central nervous system hemangioblastoma, and pancreatic neuroendocrine tumor
A2: Population
B4: Epidemiology | M4: Model Flowchart(당해연도 신규 환자)
B6: 1. Population inputs | F6: Input | G6: Source | M6: Adult Q85.8 population
C7: % Annual growth rate of Q85.8(달리 분류되지 않는 모반증) incident case | F7: 0.0804 | G7: 보건의료빅데이터개방시스템
C8: % proportion of VHL in Q85.8 | F8: 0.27 | G8: Park TY 등(2015) | M8: Adult patients with VHL disease
F9: * Yoon SJ 등 (2022) 은 국내 VHL 환자를 분석한 국내 자료원으로서, 이를 기반으로 기본 분석을 시행하였습니다. 다만, 국내가 아닌 글로벌 데이터에 따른 종양 발병률에 대해서도 참고자료원으로서 drop-down으로 함께 제출합니다. (노란색 셀에 drop down 옵션 있음)
I10: Yoon SJ 등(2022)
B12: 2. VHL 환자 중 RCC환자 비율 | F12: Input | G12: Source | M12: VHL-associated RCC | R12: VHL-associated CNS-Hb | W12: VHL-associated pNET
C13: % prevalence VHL-RCC patients | F13: =IF(G13="Yoon SJ 등(2022)","52"%,"30%") -> 0.52 | G13: Yoon SJ 등(2022)
M14: Total (VHL-RCC) AND (VHL-CNS Hb) AND (VHL-pNET)
B15: 3. VHL 환자 중 CNS Hb 환자 비율 | F15: Input | G15: Source
C16: % prevalence VHL-CNS HB patients | F16: =IF(G16="Yoon SJ 등(2022)","76"%,"49%") -> 0.76 | G16: Yoon SJ 등(2022) | M16: Substract Overlapping
B18: 4. VHL 환자 중 pNET 환자 비율 | F18: Input | G18: Source | M18: Unsuitable or Inoperable | R18: Unsuitable or Inoperable | W18: Unsuitable or Inoperable
C19: % Incidence VHL-pNET patients | F19: =IF(G19="Yoon SJ 등(2022)","8"%,"10%") -> 0.08 | G19: Yoon SJ 등(2022)
M20: 당해연도 신규 환자 :adult patients with VHL associated RCC/ CNS-Hb and/or pNET, whom surgery is unsuitable or inoperable
B21: 5. 중복 환자 제외: VHL-associated RCC, CNS, and/or pNET | F21: Input | G21: Source
C22: % unique patients in the VHL-associated RCC, CNS, and/or pNET target populations | F22: =Reference!$F$56 -> 0.65327511 | G22: Sundaram, M., et al. (2025)
B24: 6. 수술이 불가능하거나 적합하지 않은 환자 비율 | F24: Input | G24: Source
F25: 0.35 | G25: NICE Assessment | M25: Model Flowchart(전체)
B27: 7. 치료 지속 비율 | F27: Input | G27: Source | M27: 당해연도 신규 환자 | R27: 전년도 유병 환자
C28: % 1- treatment discontinuation/yr | E28: 1년차 | F28: 0.93442623 | G28: Jonasch et al, 2021
E29: 2년차 | F29: 0.86885246
B30: Population | P30: 재발로 수술 필요 환자 | T30: 전년도 누적(치료 지속)
C32: 1. 신규 대상 환자수 | P32: Unsuitable or Inoperable | X32: 치료 중단
C33: 웰리렉정은 대상 적응증에 승인된 최초의 약제이므로 그간 치료제가 없어 누적되었던 환자가 일시적으로 급여 1차년도에 한번에 신규 유입된다고 가정하였다.
C34: Parameters | E34: 2027년(1차년도) | G34: 2028년(2차년도) | I34: 2029년(3차년도) | M34: 당해연도 전체 대상 환자
E35: 당해년도 신규 | F35: 전년도 누적 | G35: 당해년도 신규 | H35: 전년도 진단환자 | I35: 당해년도 신규 | J35: 전년도 진단환자
C36: 1) 신규 성인 VHL 환자수 | E36: 429 | G36: =Setting!H46-Setting!H45 -> 34.498672 | H36: =E36-E59 -> 296 | I36: =Setting!H47-Setting!H46 -> 37.272146 | J36: =SUM(G36:H36)-SUM(G54:H54) -> 314.49867
C37: VHL - RCC | D37: 2) VHL-RCC인 환자 | E37: =E36*$F$13 -> 223.08 | G37: =G36*$F$13 -> 17.93931 | H37: =H36*$F$13 -> 153.92 | I37: =I36*$F$13 -> 19.381516 | J37: =J36*$F$13 -> 163.53931
C38: VHL- CNS Hb | D38: 3) VHL-CNS Hb인 환자 | E38: =E36*$F$16 -> 326.04 | G38: =G36*$F$16 -> 26.218991 | H38: =H36*$F$16 -> 224.96 | I38: =I36*$F$16 -> 28.326831 | J38: =J36*$F$16 -> 239.01899
C39: VHL-pNET | D39: 4) VHL-pNET인 환자 | E39: =E36*$F$19 -> 34.32 | G39: =G36*$F$19 -> 2.7598938 | H39: =H36*$F$19 -> 23.68 | I39: =I36*$F$19 -> 2.9817717 | J39: =J36*$F$19 -> 25.159894
C40: 5) RCC, CNS Hb, pNET 환자수 | E40: =ROUND(SUM(E37:E39),0) -> 583 | G40: =ROUND(SUM(G37:G39),0) -> 47 | H40: =ROUND(SUM(H37:H39),0) -> 403 | I40: =ROUND(SUM(I37:I39),0) -> 51 | J40: =ROUND(SUM(J37:J39),0) -> 428
C41: 6) 중복제외 된 RCC, CNS Hb, pNET 환자수 | E41: =ROUND(E40*$F$22,0) -> 381 | G41: =ROUND(G40*$F$22,0) -> 31 | H41: =ROUND(H40*$F$22,0) -> 263 | I41: =ROUND(I40*$F$22,0) -> 33 | J41: =ROUND(J40*$F$22,0) -> 280
C42: *전년도 진단 환자 중 종양 성장으로 수술 필요 환자 | H42: =ROUND(H41*Reference!$E$34,0) -> 14 | J42: =ROUND(J41*Reference!$E$34,0) -> 15
C43: 7) 수술이 적합하지 않거나 불가능한 환자 | E43: =ROUND(E41*$F$25,0) -> 133 | G43: =ROUND(G41*$F$25,0) -> 11 | H43: =ROUND(H42*$F$25,0) -> 5 | I43: =ROUND(I41*$F$25,0) -> 12 | J43: =ROUND(J42*$F$25,0) -> 5
C45: 2. 전년도 누적 환자수
C46: 웰리렉정은 허용할 수 없는 독성 또는 질병의 진행이 나타날때까지 투여 함.
C47: Parameters | E47: =E34 -> 2027년(1차년도) | G47: =G34 -> 2028년(2차년도) | I47: =I34 -> 2029년(3차년도)
E48: 당해년도 신규 | F48: 전년도 누적 | G48: 당해년도 신규 | H48: 전년도 누적 | I48: 당해년도 신규 | J48: 전년도 누적
...

Sheet Cost_drug
B1: =title -> Budget impact model of belzutifan as a treatment for Von Hippel Lindau Disease-associated renal cell carcinoma, central nervous system hemangioblastoma, and pancreatic neuroendocrine tumor
A3: Cost_drug
C6: Costs
C7: ▶Belzutifan/정
E8: 표시가 | F8: 195475
E9: 환급률 | F9: 0.2
E10: 실제가 | F10: =ROUNDDOWN(F8*(1-F9),0) -> 156380
B13: A8 adjusted price | E13: Updated on 2026-03-18
B15: 평균환율 | C15: 국가 | D15: 환율 Index | E15: 용량 | F15: List price/package(90T) | G15: List price/tablet | H15: List price/tablet | I15: 국가 공장도 출하 비율 | J15: 부가가치세율 | K15: 유통거래폭 | L15: A8 adjusted price(KRW)
B16: =MID(Ref_하나은행!A3,6,25) -> 2023-02-28 ~ 2025-02-28 | F16: Local currency | G16: Local currency | H16: KRW | I16: 2025.3월 기준 | J16: 0.1 | K16: 0.0869 | L16: KRW
B17: =VLOOKUP(D17,Ref_하나은행!A:B,2,0) -> 1707.75 | C17: UK (￡) | D17: 영국 GBP | E17: 40mg | F17: 11936.7 | G17: =F17/90 -> 132.63 | H17: =G17*B17 -> 226498.88 | I17: 0.73 | J17: =H17*I17*(1+$J$16) -> 181878.6 | K17: =J17*(1+$K$16) -> 197683.85 | L17: =H17*0.73*1.1*1.0869 -> 197683.85
B18: =VLOOKUP(D18,Ref_하나은행!A:B,2,0) -> 1351.85 | C18: USA ($) | D18: 미국 USD | E18: 40mg | F18: 31162.5 | G18: =F18/90 -> 346.25 | H18: =G18*B18 -> 468078.06 | I18: 0.74 | J18: =H18*I18*(1+$J$16) -> 381015.54 | K18: =J18*(1+$K$16) -> 414125.79 | L18: =H18*0.74*1.1*1.0869 -> 414125.79
B19: =VLOOKUP(D19,Ref_하나은행!A:B,2,0) -> 988.63 | C19: Canada(CAD$) | D19: 캐나다 CAD | E19: 40mg | F19: =G19*90 -> 19199.7 | G19: 213.33 | H19: =G19*B19 -> 210904.44 | I19: 0.81 | J19: =H19*I19*(1+$J$16) -> 187915.85 | K19: =J19*(1+$K$16) -> 204245.74 | L19: =H19*0.81*1.1*1.0869 -> 204245.74
B20: =VLOOKUP(D20,Ref_하나은행!A:B,2,0)/100 -> 9.1559 | C20: Japan (￥) | D20: 일본 JPY | E20: 40mg | F20: =G20*90 -> 1972512 | G20: 21916.8 | H20: =G20*B20 -> 200668.03 | I20: 0.79 | J20: =H20*I20*(1+$J$16) -> 174380.52 | K20: =J20*(1+$K$16) -> 189534.18 | L20: =H20*0.79*1.1*1.0869 -> 189534.18
B21: =VLOOKUP(D21,Ref_하나은행!A:B,2,0) -> 1457.84 | C21: France (€) | D21: 유로 EUR | E21: 40mg | F21: n/a | G21: n/a | H21: n/a | I21: 0.77 | J21: =IFERROR(H21*(1+$J$16),"n/a") -> n/a | K21: =IFERROR(J21*(1+$K$16),"n/a") -> n/a | L21: =IFERROR(ROUNDDOWN(H21*I21*(1+J21)*(1+K21),0.1),"n/a") -> n/a
B22: =VLOOKUP(D22,Ref_하나은행!A:B,2,0) -> 1457.84 | C22: Germany (€) | D22: 유로 EUR | E22: 40mg | F22: 17830.31 | G22: =F22/90 -> 198.11456 | H22: =G22*B22 -> 288819.32 | I22: =(((((G22/1.19)-8.35)/1.03)-0.7)/1.0315)*0.93 -> 137.78877 | J22: =I22*(1+J16)*B22 -> 220961.38 | K22: =J22*(1+$K$16) -> 240162.93 | L22: =IFERROR(ROUNDDOWN((((((G22/1.19)-8.35)/1.03)-0.7)/1.0315)*0.93*1.1*1.0869*B22,0.1),"n/a") -> 240162
B23: =VLOOKUP(D23,Ref_하나은행!A:B,2,0) -> 1457.84 | C23: Italy (€) | D23: 유로 EUR | E23: 40mg | F23: n/a | G23: n/a | H23: n/a | I23: 0.93 | J23: =IFERROR(H23*(1+$J$16),"n/a") -> n/a | K23: =IFERROR(J23*(1+$K$16),"n/a") -> n/a | L23: =IFERROR(ROUNDDOWN(H23*I23*(1+J23)*(1+K23),0.1),"n/a") -> n/a
B24: =VLOOKUP(D24,Ref_하나은행!A:B,2,0) -> 1522.62 | C24: switzerland (℉) | D24: 스위스 CHF | E24: 40mg | F24: n/a | G24: n/a | H24: n/a | I24: 0.73 | J24: =IFERROR(H24*(1+$J$16), "n/a") -> n/a | K24: =IFERROR(J24*(1+$K$16),"n/a") -> n/a | L24: =IFERROR(ROUNDDOWN(H24*I24*(1+J24)*(1+K24),0.1),"n/a") -> n/a
B26: A8 조정 최저가 | C26: KRW
B27: list price/tablet | C27: =MIN(L17:L19) -> 197683.85
B29: A8 조정 평균가 | C29: KRW
B30: list price/tablet | C30: =AVERAGE(L17:L22) -> 249150.31

Sheet Cost_treatment
B1: =title -> Budget impact model of belzutifan as a treatment for Von Hippel Lindau Disease-associated renal cell carcinoma, central nervous system hemangioblastoma, and pancreatic neuroendocrine tumor
A3: Treatment cost
B5: Cost
C7: Belzutifan | D7: =Cost_drug!F10 -> 156380
B9: Treatment duration
B11: 1. Treatment duration
C12: 치료법 | D12: 평균 치료 기간(단위:월)
D13: 1차년도 | E13: 2차년도 | F13: 3차년도
C14: =Tx_1 -> Belzutifan | D14: 12 | E14: 12 | F14: 12
C15: Active surveillance | D15: 12 | E15: 12 | F15: 12
C16: *Belzutifan은 약물로 인한 이상 반응 및 견딜 수 없는 독성이 일어나기 전까지 투여 가능하다.
B18: Treatment acquistion cost
B20: 1. Monthly drug cost
C21: 의약품 | D21: 단위용량 | E21: 단위비용 | F21: 1일 투여용량 | G21: 1일 투여량(tablets) | H21: 1일 의약품비(원/일) | I21: 월별 의약품비(원/월)
C22: Belzutifan | D22: 40mg tablet | E22: =Cost_drug!F10 -> 156380 | F22: 120mg | G22: 3 | H22: =E22*G22 -> 469140 | I22: =H22*(365/12) -> 14269675
C23: active surveillance | D23: n/a | E23: 0 | F23: n/a | G23: n/a | H23: 0 | I23: 0
B26: 2. Yearly drug cost
C27: 치료법 | D27: 연도별 예상되는 평균 치료 기간(mean DoT), 단위: 년 | G27: Source
D28: 1차년도 | E28: 2차년도 | F28: 3차년도
C29: =Tx_1 -> Belzutifan | D29: =D14*$I$22 -> 171236100 | E29: =E14*$I$22 -> 171236100 | F29: =F14*$I$22 -> 171236100 | G29: Jonash 등(2021)
C30: Surgery | D30: =D15*$I$23 -> 0 | E30: =E15*$I$23 -> 0 | F30: =F15*$I$23 -> 0 | G30: active surveillance 정의
B34: Biomarker test cost
C36: 검사항목 | D36: 수가코드 | E36: 의료기관 | F36: 단가1) | G36: 종별가산율적용(원)2) | H36: 방문비율적용(원)3)
C37: VHL gene | D37: C5806146 | E37: 상급종합병원 | F37: 155990 | G37: =F37*(1+#REF!) -> #REF! | H37: =SUMPRODUCT(G37:G38,#REF!) -> #REF!
E38: 종합병원 | G38: =F37*(1+#REF!) -> #REF!
C39: 1) 2023.01.01. 기준 의·치과한방 등 수가파일, 건강보험심사평가원 2) 2023년 2월판 건강보험요양급여비용, 건강보험심사평가원: 종별가산율 상급종합병원 30%, 종합병원 25% 3) 질병 소분류(Q85.8) 요양기관 종별현황, 보건의료빅데이터 개방시스템: 종별방문비율 상급종합병원 84%, 종합병원 16%

Sheet Budget Impact
B1: =title -> Budget impact model of belzutifan as a treatment for Von Hippel Lindau Disease-associated renal cell carcinoma, central nervous system hemangioblastoma, and pancreatic neuroendocrine tumor
B7: Summary
B9: 1. 시장점유율에 따른 예상사용량 | F9: Base scenario
F10: Base scneario | H10: Base scneario
C11: 당해연도 시장점유율
C12: 구분 | D12: 2026 | E12: =D12+1 -> 2027 | F12: =E12+1 -> 2028 | G12: =F12+1 -> 2029
C13: belzutifan | D13: 0 | E13: 0.95 | F13: 0.975 | G13: 1
C14: Active surveillance | D14: 1 | E14: =(1-E$13)*$D14 -> 0.05 | F14: =(1-F$13)*$D14 -> 0.025 | G14: =(1-G$13)*$D14 -> 0
C16: 전년도 누적 시장점유율
C17: 구분 | D17: 전년도 belzutifan 치료 지속 누적 환자
C18: belzutifan | D18: 1
C19: Active surveillance | D19: 0
C21: 예상 사용량
C22: 구분 | D22: =E12 -> 2027 | E22: =F12 -> 2028 | F22: =G12 -> 2029
C23: 예상 사용량(tablets/년) | D23: =D45 -> 137970 | E23: =E45 -> 153300 | F23: =F45 -> 162060
B26: 신청약제의 예상사용량
B28: 1. 신청약제의 예상 점유율
C29: 구분 | E29: =E12 -> 2027 | I29: =F12 -> 2028 | M29: =G12 -> 2029
E30: 당해연도 신규 | G30: 전년도 누적 | I30: 당해연도 신규 | K30: 전년도 누적 | M30: 당해연도 신규 | O30: 전년도 누적
C31: 예상 환자수(명) | E31: =Epi_Population!E59 -> 133 | G31: 0 | I31: =SUM(Epi_Population!G54:H54) -> 16 | K31: =Epi_Population!H49 -> 124.27869 | M31: =SUM(Epi_Population!I54:J54) -> 17 | O31: =Epi_Population!J49 -> 130.5082
C32: 구분 | E32: 당해연도 신규 | G32: 전년도 누적 | I32: 당해연도 신규 | K32: 전년도 누적 | M32: 당해연도 신규 | O32: 전년도 누적
E33: 시장점유율 | F33: 환자수 | G33: 시장점유율 | H33: 환자수 | I33: 시장점유율 | J33: 환자수 | K33: 시장점유율 | L33: 환자수 | M33: 시장점유율 | N33: 환자수 | O33: 시장점유율 | P33: 환자수
C34: 신청약제 도입이전 | D34: belzutifan | E34: =$D$13 -> 0 | F34: =ROUND($E$31*E34,0) -> 0 | G34: =$D$13 -> 0 | H34: =ROUND($G$31*G34,0) -> 0 | I34: =$D$13 -> 0 | J34: =ROUND($I$31*I34,0) -> 0 | K34: =$D$13 -> 0 | L34: =ROUND($K$31*K34,0) -> 0 | M34: =$D$13 -> 0 | N34: =ROUND($M$31*M34,0) -> 0 | O34: =$D$13 -> 0 | P34: =ROUND($O$31*O34,0) -> 0
D35: =C19 -> Active surveillance | E35: =$D$14 -> 1 | F35: =ROUND($E$31*E35,0) -> 133 | G35: =$D$14 -> 1 | H35: =ROUND($G$31*G35,0) -> 0 | I35: =$D$14 -> 1 | J35: =ROUND($I$31*I35,0) -> 16 | K35: =$D$14 -> 1 | L35: =ROUND($K$31*K35,0) -> 124 | M35: =$D$14 -> 1 | N35: =ROUND($M$31*M35,0) -> 17 | O35: =$D$14 -> 1 | P35: =ROUND($O$31*O35,0) -> 131
C36: 신청약제 도입이후 | D36: belzutifan | E36: =E13 -> 0.95 | F36: =ROUND($E$31*E36,0) -> 126 | G36: =$D$18 -> 1 | H36: =ROUND($G$31*G36,0) -> 0 | I36: =F13 -> 0.975 | J36: =ROUND($I$31*I36,0) -> 16 | K36: =$D$18 -> 1 | L36: =ROUND($K$31*K36,0) -> 124 | M36: =G13 -> 1 | N36: =ROUND($M$31*M36,0) -> 17 | O36: =$D$18 -> 1 | P36: =ROUND($O$31*O36,0) -> 131
D37: =C19 -> Active surveillance | E37: =E14 -> 0.05 | F37: =ROUND($E$31*E37,0) -> 7 | G37: =$D$19 -> 0 | I37: =F14 -> 0.025 | J37: =ROUND($I$31*I37,0) -> 0 | K37: =$D$19 -> 0 | M37: =G14 -> 0 | N37: =ROUND($M$31*M37,0) -> 0 | O37: =$D$19 -> 0
B39: 2. 신청약제의 예상 사용량
C40: 구분 | D40: =E12 -> 2027 | E40: =F12 -> 2028 | F40: =G12 -> 2029
C41: 신청약제 투여 예상 환자수(명) | D41: =SUM(F36,H36) -> 126 | E41: =SUM(J36,L36) -> 140 | F41: =SUM(N36,P36) -> 148
C42: 1회당 투여량(tablets) | D42: 3 | E42: 3 | F42: 3
C43: 연간 투약일 | D43: =Cost_treatment!D14*(365/12) -> 365 | E43: =Cost_treatment!E14*(365/12) -> 365 | F43: =Cost_treatment!F14*(365/12) -> 365
C44: 치료기간동안 투여량 (tablets/치료기간) | D44: =D42*D43 -> 1095 | E44: =E42*E43 -> 1095 | F44: =F42*F43 -> 1095
C45: 예상 사용량(tablets/년) | D45: =D41*D44 -> 137970 | E45: =E41*E44 -> 153300 | F45: =F41*F44 -> 162060
B48: 신청약제 도입시 연간추정 요양급여비용
C50: 구분 | E50: =E12 -> 2027 | F50: =F12 -> 2028 | G50: =G12 -> 2029
E51: 의약품비 | F51: 의약품비 | G51: 의약품비
C52: Belzutifan | E52: =D45*Cost_treatment!E22 -> 21575748600 | F52: =E45*Cost_treatment!E22 -> 23973054000 | G52: =F45*Cost_treatment!E22 -> 25342942800
B54: 재정영향검토
B56: 신청약제 도입 이후 총 치료비용(=의약품비)로 인한 재정영향
C57: 구분 | E57: =E12 -> 2027 | F57: =F12 -> 2028 | G57: =G12 -> 2029
...

Sheet Reference
B2: Source: 보건의료빅데이터개방시스템 | M2: Source: Binderup M L 등,2013 | Q2: 기준일 : 2023-02-28 ~ 2025-02-28 고시회차 : 최종 [조회시각 : 2026-03-18 22:44:55]
B3: '4단질병_성별연령5세구간별현황(단위_명, 일, 건, 천원)_2018_2024 | M3: VHL 증후군 징후에 따른 발생 빈도 | Q3: 평균환율조회
D5: 심사년도 | E5: 2018년 | F5: 2019년 | G5: 2020년 | H5: 2021년 | I5: 2022년 | J5: 2023년 | K5: 2024년 | M5: 징후 | N5: VHL환자의 대략적인 발생 빈도,% | O5: VHL환자의 대략적인 발생 빈도,%범위 | Q5: 통화 | R5: 매매기준율
B6: 항목 | C6: 성별구분 | D6: 연령구분5세 | E6: 환자수 | F6: 환자수 | G6: 환자수 | H6: 환자수 | I6: 환자수 | J6: 환자수 | K6: 환자수 | M6: 신세포암(RCC) | N6: 0.3 | O6: (5,86) | Q6: 미국 USD | R6: 1351.85
B7: Q858 | C7: 계 | D7: 계 | E7: 951 | F7: 1005 | G7: 1055 | H7: 1125 | I7: 1142 | J7: 1286 | K7: 1333 | M7: 중추신경계 혈관모세포종(CNS Hb) | Q7: 유로 EUR | R7: 1457.84
M8: 소뇌 혈관모세포종 | N8: 0.49 | O8: (35,79) | Q8: 일본 JPY | R8: 915.59
M9: 척수 혈관모세포종 | N9: 0.27 | O9: (7,53) | Q9: 중국 CNY | R9: 188.06
M10: 뇌간 혈관모세포종 | N10: 0.16 | O10: (4,22) | Q10: 영국 GBP | R10: 1707.75
M11: 대뇌 혈관모세포종 | N11: 0.04 | O11: (1,7) | Q11: 캐나다 CAD | R11: 988.63
M12: 췌장 신경 내분비종양(pNET) | N12: 0.1 | O12: (1,17) | Q12: 스위스 CHF | R12: 1522.62
B14: Source: LITESPARK-004, Jonasch et al, 2021
B15: 치료 중단 비율
B17: 치료 중단 비율 | C17: 1 | D17: 2 | E17: 3 | F17: 4 | G17: 5
B18: LS-004 | C18: 0.93442623 | D18: 0.86885246 | E18: 0.72131148 | F18: 0.59016393 | G18: 0.55737705
B21: Source: Garrido 2024, Jilg et al., de Mestier et al.
B22: 재수술 비율
B24: 구분 | C24: 1년 재수술 위험 | D24: 5년 누적 재수술 위험 | E24: 10년 누적 재수술 위험
B25: VHL-RCC | C25: 0.046 | D25: 0.21 | E25: 0.42
B26: VHL-CNS Hb | C26: 0.067 | D26: 0.285 | E26: 0.471
B27: VHL-pNET | C27: 0 | D27: 0.05 | E27: 0.118
B30: 구분 | C30: 질환유병비율 | D30: 유병률 가중조정 | E30: 1Y Risk | F30: 2Y Risk | G30: 3Y Risk | H30: 4Y Risk | I30: 5Y Risk | J30: 6Y Risk | K30: 7Y Risk | L30: 8Y Risk
B31: VHL-RCC | C31: 0.52 | D31: =C31/$C$34 -> 0.38235294 | E31: 0.046 | F31: 0.046 | G31: 0.045 | H31: 0.046 | I31: 0.046 | J31: 0.061 | K31: 0.061 | L31: 0.06
B32: VHL-CNS Hb | C32: 0.76 | D32: =C32/$C$34 -> 0.55882353 | E32: 0.067 | F32: 0.066 | G32: 0.065 | H32: 0.064 | I32: 0.063 | J32: 0.06 | K32: 0.061 | L32: 0.059
B33: VHL-pNET | C33: 0.08 | D33: =C33/$C$34 -> 0.058823529 | E33: 0 | F33: 0.025 | G33: 0.026 | H33: 0 | I33: 0 | J33: 0.014 | K33: 0.014 | L33: 0.014
C34: 1.36 | D34: =SUM(D31:D33) -> 1 | E34: =$D$31*E31+$D$32*E32+$D$33*E33 -> 0.055029412 | F34: =$D$31*F31+$D$32*F32+$D$33*F33 -> 0.055941176 | G34: =$D$31*G31+$D$32*G32+$D$33*G33 -> 0.055058824 | H34: =$D$31*H31+$D$32*H32+$D$33*H33 -> 0.053352941 | I34: =$D$31*I31+$D$32*I32+$D$33*I33 -> 0.052794118 | J34: =$D$31*J31+$D$32*J32+$D$33*J33 -> 0.057676471 | K34: =$D$31*K31+$D$32*K32+$D$33*K33 -> 0.058235294 | L34: =$D$31*L31+$D$32*L32+$D$33*L33 -> 0.056735294
B37: Source: Sundaram, M., et al. 2025
B38: Combined population
B40: 문헌 상호베타 분포 (220명) | F40: 상호베타 값을 그룹별 재환산
B41: 구간 | C41: 환자 수 | D41: 비율 | F41: 질환 | H41: 환자수 | I41: 그룹
B42: RCC + pNET + CNS Hb | C42: 77 | D42: =C42/220 -> 0.35 | F42: RCC | H42: =SUM(C42,C43,C46,C47) -> 146 | I42: 1 | K42: *그룹 1-2+3 이 중복을 제거한 환자수
B43: RCC + CNS Hb only | C43: 43 | D43: =C43/220 -> 0.19545455 | F43: CNS Hb | H43: =SUM(C42,C43,C44,C45) -> 190 | I43: 1 | K43: =SUM(H42:H44)-SUM(H45:H47)+H48 -> 220
B44: CNS Hb only | C44: 39 | D44: =C44/220 -> 0.17727273 | F44: pNET | H44: =SUM(C42,C45,C47,C48) -> 122 | I44: 1 | K44: *2와 3은 각 질환을 중복으로 가지고 있는 환자 그룹
B45: pNET + CNS Hb only | C45: 31 | D45: =C45/220 -> 0.14090909 | F45: RCC+CNS Hb | H45: =SUM(C43,C42) -> 120 | I45: 2 | K45: 2의 비율 | L45: =SUM(H45:H47)/SUM(H42:H44) -> 0.68777293
B46: RCC only | C46: 16 | D46: =C46/220 -> 0.072727273 | F46: RCC+pNET | H46: =SUM(C47,C42) -> 87 | I46: 2 | K46: 3의 비율 | L46: =H48/SUM(H42:H44) -> 0.16812227
B47: RCC + pNET only | C47: 10 | D47: =C47/220 -> 0.045454545 | F47: CNS Hb+pNET | H47: =SUM(C42,C45) -> 108 | I47: 2 | K47: *질환별 유병환자수(그룹1) - 그룹1x68.78% + 그룹1(16.81%) = 중복을 제거한 환자수
B48: pNET only | C48: 4 | D48: =C48/220 -> 0.018181818 | F48: RCC + pNET + CNS Hb | H48: =C42 -> 77 | I48: 3
B50: Source: Yoon SJ., et al.2 022
B52: Total Patients | C52: 50 | D52: Frequency in patients
B53: RCC | C53: 0.52 | D53: =C53*$C$52 -> 26 | F53: =D56*L45 -> 46.768559 | G53: 2그룹 추계값 (RCC+CNS Hb / RCC+pNET / CNS Hb + pNET)
B54: CNS Hb | C54: 0.76 | D54: =C54*$C$52 -> 38 | F54: =D56*L46 -> 11.432314 | G54: 3그룹 추계값 (RCC+CNS Hb + pNET)
...

Sheet Ref_하나은행
A1: 평균환율
A3: 기준일 : 2023-02-28 ~ 2025-02-28 고시회차 : 최종 [조회시각 : 2026-03-18 22:44:55]
A4: 통화 | B4: 매매기준율
A5: 미국 USD | B5: 1351.85
A6: 유로 EUR | B6: 1457.84
A7: 일본 JPY | B7: 915.59
A8: 중국 CNY | B8: 188.06
A9: 영국 GBP | B9: 1707.75
A10: 캐나다 CAD | B10: 988.63
A11: 스위스 CHF | B11: 1522.62
A12: 홍콩 HKD | B12: 173.06
A13: 스웨덴 SEK | B13: 127.14
A14: 호주 AUD | B14: 887.45
A15: 덴마크 DKK | B15: 195.52
A16: 노르웨이 NOK | B16: 125.71
... A62: 우즈베키스탄 UZS | B62: 0.11
